Workbook

Sheet 00_Synthese
A1: Tantalus Frontier — V162
A2: 00_Synthese
A3: Prépublication : implémentation et validation du commit restent distinctes.
A5: Indicateur | E5: Compte vérifiable
A7: Identités du roster conservées | E7: =COUNTA('08_Roster'!A6:A194) -> 189
A8: Rigs natifs concernés | E8: =SUM('08_Roster'!D6:D194) -> 4
A9: Séquences techniques cumulées | E9: =COUNTA('03_Sequences'!A6:A45) -> 40
A10: Points clés explicitement écrits | E10: =SUM('03_Sequences'!E6:E45) -> 200
A11: Présentations V146 conservées | E11: =COUNTA('01_Presentations'!A6:A45) -> 40
A12: Présentations techniquement raccordées | E12: =COUNTA('01_Presentations'!E6:E45) -> 40
A13: Tâches ART153 conservées | E13: =COUNTA('02_ART153'!A6:A33) -> 28
A14: Annexes avec affectation conditionnelle | E14: =COUNTIF('04_Annexes'!G6:G24,"Affectation technique conditionnelle") -> 19
A15: Contrats narratifs Forge suivis | E15: =COUNTA('05_Forge'!A6:A17) -> 12
A16: Clôtures artistiques complètes | E16: =SUM('01_Presentations'!G6:G45) -> 0
A17: Présentations approuvées 1:1 | E17: =SUM('01_Presentations'!H6:H45) -> 0
A18: Accès d’opérations actifs déjà jouables | E18: =SUM('10_Operations'!E6:E26) -> 21
A19: Rigs avec sortie spatiale bornée | E19: =COUNTA('12_TrialsSortie'!A6:A9) -> 4
A20: Identités avec registre de preuve distinct | E20: =COUNTA('13_Preuve1to1'!A6:A194) -> 189
A21: Identités certifiées 1:1 à l’œuvre | E21: =SUM('13_Preuve1to1'!K6:K194) -> 0
A22: Lots techniques V159 suivis | E22: =COUNTA('15_LotsV159'!A6:A6) -> 1
A23: Réceptions natives adaptées | E23: =COUNTIF('02_ART153'!E6:E33,"Implémenté (adaptation native)") -> 3
A24: Chantiers utilisateur V160 distincts des 68 tâches Trials | E24: =COUNTA('18_ChantiersV160'!A6:A9) -> 4
A25: Clôtures artistiques des quatre chantiers V160 | E25: =SUM('18_ChantiersV160'!L6:L9) -> 0
A26: Chantiers V160 certifiés 1:1 | E26: =SUM('18_ChantiersV160'!M6:M9) -> 0
A27: Manquants repris V161 distincts des 68 tâches Trials | E27: =COUNTA('21_ChantiersV161'!A6:A8) -> 3
A28: Clôtures artistiques V161 | E28: =SUM('21_ChantiersV161'!I6:I8) -> 0
A29: Certifications 1:1 V161 | E29: =SUM('21_ChantiersV161'!J6:J8) -> 0
A30: Périmètres hors Forge V162 distincts des 68 tâches Trials | E30: =COUNTA('22_ChantiersV162'!A6:A9) -> 4
A31: Clôtures artistiques V162 | E31: =SUM('22_ChantiersV162'!I6:I9) -> 0
A32: Certifications 1:1 V162 | E32: =SUM('22_ChantiersV162'!J6:J9) -> 0

Sheet 01_Presentations
A1: Tantalus Frontier — V162
A2: 01_Presentations
A3: Prépublication : implémentation et validation du commit restent distinctes.
A5: Présentation V146 | B5: Identité | C5: Séquence prévue | D5: État | E5: Implémentation V155 | F5: Livré / manquant | G5: Clos artistiquement | H5: Approuvé 1:1
A6: prowler::intro | B6: Prowler | C6: Intro standard | D6: Partiel | E6: prowler::intro | F6: Entrée V155 conservée sur le rig natif. Adaptation de simulation ; dessins complets, audio et relevés d’œuvre restent ouverts. Aucun lot artistique clos ni certification 1:1. | G6: 0 | H6: 0
A7: prowler::intro-rival | B7: Prowler | C7: Intro de rivalité | D7: Partiel | E7: prowler::intro-rival | F7: Réponse à la famille effective de l’adversaire, y compris hybride, pendant sa présentation ; aucune rivalité historique affirmée. Adaptation de simulation ; dessins complets, audio et relevés d’œuvre restent ouverts. Aucun lot artistique clos ni certification 1:1. | G7: 0 | H7: 0
A8: prowler::outro | B8: Prowler | C8: Outro | D8: Partiel | E8: prowler::outro | F8: V157 ajoute une retombée de rendu bornée si le verdict fige le rig en l’air, puis une sortie vers les bords. Corps physiques et verdict inchangés ; phases historiques au sol intactes. Dessins, audio et revue 1:1 restent ouverts. | G8: 0 | H8: 0
A9: prowler::win-r1 | B9: Prowler | C9: Victoire de première manche | D9: Partiel | E9: prowler::round-win | F9: Réaction V155 réversible de victoire de manche conservée. Adaptation de simulation ; dessins complets, audio et relevés d’œuvre restent ouverts. Aucun lot artistique clos ni certification 1:1. | G9: 0 | H9: 0
A10: prowler::lose-r1 | B10: Prowler | C10: Défaite de première manche | D10: Partiel | E10: prowler::round-loss | F10: Récupération V155 réversible de défaite de manche conservée. Adaptation de simulation ; dessins complets, audio et relevés d’œuvre restent ouverts. Aucun lot artistique clos ni certification 1:1. | G10: 0 | H10: 0
A11: prowler::win-final | B11: Prowler | C11: Victoire finale | D11: Partiel | E11: prowler::outro-win | F11: Pose V155 de victoire terminale conservée ; aucun second résultat ni paiement. Adaptation de simulation ; dessins complets, audio et relevés d’œuvre restent ouverts. Aucun lot artistique clos ni certification 1:1. | G11: 0 | H11: 0
A12: prowler::lose-final | B12: Prowler | C12: Défaite finale | D12: Partiel | E12: prowler::outro-loss | F12: Pose V155 de défaite terminale conservée ; ce n’est pas une chute complète. Adaptation de simulation ; dessins complets, audio et relevés d’œuvre restent ouverts. Aucun lot artistique clos ni certification 1:1. | G12: 0 | H12: 0
A13: prowler::draw | B13: Prowler | C13: Égalité | D13: Partiel | E13: prowler::draw | F13: Réaction sans vainqueur sur égalité réelle de manche ou de match ; ne force aucun résultat. Adaptation de simulation ; dessins complets, audio et relevés d’œuvre restent ouverts. Aucun lot artistique clos ni certification 1:1. | G13: 0 | H13: 0
A14: prowler::taunt | B14: Prowler | C14: Provocation | D14: Partiel | E14: prowler::taunt | F14: Commande T ou bouton DÉFI pendant le combat ; le bouton rend le focus au canvas quand le combat accepte les commandes. Annulation par déplacement, attaque, garde ou impact. Adaptation de simulation ; dessins complets, audio et relevés d’œuvre restent ouverts. Aucun lot artistique clos ni certification 1:1. | G14: 0 | H14: 0
A15: prowler::rematch | B15: Prowler | C15: Début de manche suivante | D15: Partiel | E15: prowler::rematch | F15: Reprise visuelle pendant le décompte existant des manches suivantes, sans nouvel équipement ni changement physique. Adaptation de simulation ; dessins complets, audio et relevés d’œuvre restent ouverts. Aucun lot artistique clos ni certification 1:1. | G15: 0 | H15: 0
A16: import-game-dd-wy-commando::intro | B16: Weyland-Yutani Commando — Altered — adaptation | C16: Intro standard | D16: Partiel | E16: import-game-dd-wy-commando::intro | F16: Entrée V155 conservée sur le rig natif. Adaptation de simulation ; dessins complets, audio et relevés d’œuvre restent ouverts. Aucun lot artistique clos ni certification 1:1. | G16: 0 | H16: 0
A17: import-game-dd-wy-commando::intro-rival | B17: Weyland-Yutani Commando — Altered — adaptation | C17: Intro de rivalité | D17: Partiel | E17: import-game-dd-wy-commando::intro-rival | F17: Réponse à la famille effective de l’adversaire, y compris hybride, pendant sa présentation ; aucune rivalité historique affirmée. Adaptation de simulation ; dessins complets, audio et relevés d’œuvre restent ouverts. Aucun lot artistique clos ni certification 1:1. | G17: 0 | H17: 0
... A45: dd-darwin-era-cultist::rematch | B45: Cultiste Darwin Era | C45: Début de manche suivante | D45: Partiel | E45: dd-darwin-era-cultist::rematch | F45: Reprise visuelle pendant le décompte existant des manches suivantes, sans nouvel équipement ni changement physique. Adaptation de simulation ; dessins complets, audio et relevés d’œuvre restent ouverts. Aucun lot artistique clos ni certification 1:1. | G45: 0 | H45: 0

Sheet 02_ART153
A1: Tantalus Frontier — V162
A2: 02_ART153
A3: Prépublication : implémentation et validation du commit restent distinctes.
A5: Tâche héritée | B5: Identité | C5: ID exact | D5: Travail | E5: État | F5: Livré / reste à produire | G5: Lot | H5: Approuvé 1:1
A6: ART153-01 | B6: Prowler | C6: prowler | D6: Références de poses et timecodes | E6: À relever | F6: Coordonnées mesurées sur le sprite du projet ; référence d’œuvre et timecodes non relevés. | G6: V154 | H6: 0
A7: ART153-02 | B7: Prowler | C7: prowler | D7: Rig et points de contact | E7: Implémenté (adaptation) | F7: Rig exact, maillage, points de contact et appuis ; source native inchangée. Validation canonique non acquise. | G7: V154 | H7: 0
A8: ART153-03 | B8: Prowler | C8: prowler | D8: Préparation / capture | E8: Partiel | F8: Anticipation du bond adaptée. | G8: V154 | H8: 0
A9: ART153-04 | B9: Prowler | C9: prowler | D9: Saisie articulée | E9: Partiel | F9: Réaction de corps debout ; mise au sol et raccords entre les deux corps à produire. | G9: V154 | H9: 0
A10: ART153-05 | B10: Prowler | C10: prowler | D10: Résistance / dégagement | E10: Partiel | F10: Réaction au progrès réel du dégagement ; chorégraphie complète à produire. | G10: V154 | H10: 0
A11: ART153-06 | B11: Prowler | C11: prowler | D11: Interruption / récupération | E11: Implémenté (adaptation) | F11: Récupération courte déclenchée par la libération réelle, sans rejouer une attaque. | G11: V154 | H11: 0
A12: ART153-07 | B12: Prowler | C12: prowler | D12: Revue deux orientations et tailles | E12: À valider | F12: Mathématiques et deux orientations couvertes par tests ; validation artistique finale et 1:1 encore ouverte. | G12: V154 | H12: 0
A13: ART153-08 | B13: Weyland-Yutani Commando — Altered — adaptation | C13: import-game-dd-wy-commando | D13: Références de poses et timecodes | E13: À relever | F13: Coordonnées mesurées sur le sprite du projet ; référence d’œuvre et timecodes non relevés. | G13: V154 | H13: 0
A14: ART153-09 | B14: Weyland-Yutani Commando — Altered — adaptation | C14: import-game-dd-wy-commando | D14: Rig et points de contact | E14: Implémenté (adaptation) | F14: Rig exact, maillage, points de contact et appuis ; source native inchangée. Validation canonique non acquise. | G14: V154 | H14: 0
A15: ART153-10 | B15: Weyland-Yutani Commando — Altered — adaptation | C15: import-game-dd-wy-commando | D15: Préparation / capture | E15: Implémenté (adaptation native) | F15: Réception bornée sur la plaque native exacte ; absorption puis raccord à la prise existante. Chorégraphie de simulation, sans mise au sol complète, pin ou référence de mouvement canonique. | G15: V158 | H15: 0
A16: ART153-11 | B16: Weyland-Yutani Commando — Altered — adaptation | C16: import-game-dd-wy-commando | D16: Saisie articulée | E16: Partiel | F16: Abaissement articulé borné sur la cible native, pieds et semelles fixes, cage des deux jambes ; ni corps couché ni pin complet. Dessins, mise au sol et raccords complets restent ouverts. | G16: V156 | H16: 0
A17: ART153-12 | B17: Weyland-Yutani Commando — Altered — adaptation | C17: import-game-dd-wy-commando | D17: Résistance / dégagement | E17: Partiel | F17: La résistance conserve l’abaissement de la cible et répond au progrès réel du dégagement. Chorégraphie de corps complète et validation artistique encore ouvertes. | G17: V156 | H17: 0
... A33: ART153-28 | B33: Cultiste Darwin Era | C33: dd-darwin-era-cultist | D33: Revue deux orientations et tailles | E33: À valider | F33: Supports, maillage et abaissement contrôlés dans les deux orientations par les tests techniques. Revue artistique finale et relevés 1:1 toujours ouverts. | G33: V156 | H33: 0

Sheet 03_Sequences
A1: Tantalus Frontier — V162
A2: 03_Sequences
A3: Prépublication : implémentation et validation du commit restent distinctes.
A5: Séquence_ID | B5: Identité | C5: Phase | D5: Durée (ms) | E5: Points clés | F5: Présentation V146 | G5: État technique | H5: Fidélité
A6: prowler::intro | B6: Prowler | C6: intro | D6: 1200 | E6: 5 | F6: prowler::intro | G6: Adaptation technique raccordée | H6: Non approuvé 1:1
A7: prowler::round-win | B7: Prowler | C7: round-win | D7: 1800 | E7: 5 | F7: prowler::win-r1 | G7: Adaptation technique raccordée | H7: Non approuvé 1:1
A8: prowler::round-loss | B8: Prowler | C8: round-loss | D8: 1800 | E8: 5 | F8: prowler::lose-r1 | G8: Adaptation technique raccordée | H8: Non approuvé 1:1
A9: prowler::outro-win | B9: Prowler | C9: outro-win | D9: 1800 | E9: 5 | F9: prowler::win-final | G9: Adaptation technique raccordée | H9: Non approuvé 1:1
A10: prowler::outro-loss | B10: Prowler | C10: outro-loss | D10: 1800 | E10: 5 | F10: prowler::lose-final | G10: Adaptation technique raccordée | H10: Non approuvé 1:1
A11: dd-darwin-era-cultist::intro | B11: Cultiste Darwin Era | C11: intro | D11: 1200 | E11: 5 | F11: dd-darwin-era-cultist::intro | G11: Adaptation technique raccordée | H11: Non approuvé 1:1
A12: dd-darwin-era-cultist::round-win | B12: Cultiste Darwin Era | C12: round-win | D12: 1800 | E12: 5 | F12: dd-darwin-era-cultist::win-r1 | G12: Adaptation technique raccordée | H12: Non approuvé 1:1
A13: dd-darwin-era-cultist::round-loss | B13: Cultiste Darwin Era | C13: round-loss | D13: 1800 | E13: 5 | F13: dd-darwin-era-cultist::lose-r1 | G13: Adaptation technique raccordée | H13: Non approuvé 1:1
A14: dd-darwin-era-cultist::outro-win | B14: Cultiste Darwin Era | C14: outro-win | D14: 1800 | E14: 5 | F14: dd-darwin-era-cultist::win-final | G14: Adaptation technique raccordée | H14: Non approuvé 1:1
A15: dd-darwin-era-cultist::outro-loss | B15: Cultiste Darwin Era | C15: outro-loss | D15: 1800 | E15: 5 | F15: dd-darwin-era-cultist::lose-final | G15: Adaptation technique raccordée | H15: Non approuvé 1:1
A16: import-game-dd-wy-commando::intro | B16: Weyland-Yutani Commando — Altered — adaptation | C16: intro | D16: 1200 | E16: 5 | F16: import-game-dd-wy-commando::intro | G16: Adaptation technique raccordée | H16: Non approuvé 1:1
A17: import-game-dd-wy-commando::round-win | B17: Weyland-Yutani Commando — Altered — adaptation | C17: round-win | D17: 1800 | E17: 5 | F17: import-game-dd-wy-commando::win-r1 | G17: Adaptation technique raccordée | H17: Non approuvé 1:1
... A45: import-game-dd-guardian::rematch | B45: Guardian — Darwin Era — adaptation | C45: rematch | D45: 3000 | E45: 5 | F45: import-game-dd-guardian::rematch | G45: Adaptation technique raccordée | H45: Non approuvé 1:1

Sheet 04_Annexes
A1: Tantalus Frontier — V162
A2: 04_Annexes
A3: Prépublication : implémentation et validation du commit restent distinctes.
A5: Annexe_ID | B5: Salle | C5: PNJ_ID | D5: Rôle | E5: Créneau déclaré | F5: Support | G5: État technique | H5: Portée / limites
A6: arrival-airlock | B6: Sas d’arrivée | C6: crew-08-maksim-orlov | D6: Sécurité des arrivées | E6: 10:30–12:00 | F6: Sol physique, y=624 | G6: Affectation technique conditionnelle | H6: Présence uniquement en phase de travail ; alertes, missions, repos et soins prioritaires. Rondes locales si rail≥70 px ; pas de trajet interannexes.
A7: logistics | B7: Soute / Logistique | C7: crew-16-cal-mercer | D7: Contrôle du fret | E7: 09:00–10:30 | F7: Passerelle physique logistique, y=468 | G7: Affectation technique conditionnelle | H7: Présence uniquement en phase de travail ; alertes, missions, repos et soins prioritaires. Rondes locales si rail≥70 px ; pas de trajet interannexes.
A8: mire-archives | B8: Archives MIRE / Palimpsest | C8: crew-01-mara-vega | D8: Revue des archives de commandement | E8: 10:30–12:00 | F8: Sol physique, y=624 | G8: Affectation technique conditionnelle | H8: Présence uniquement en phase de travail ; alertes, missions, repos et soins prioritaires. Rondes locales si rail≥70 px ; pas de trajet interannexes.
A9: synthetic-bay | B9: Baie synthétique | C9: crew-05-bishop-9 | D9: Diagnostic synthétique | E9: 09:00–10:30 | F9: Sol physique, y=624 | G9: Affectation technique conditionnelle | H9: Affectation native conditionnelle ; V159 suit le même BISHOP depuis science-lab par le sas apparié et le retour. Alerte : retrait réel prioritaire aux minuteurs, réservation dès le corps sur l’ouverture même à progression zéro, marche native pilotée par distance. Missions et soins prioritaires ; quarantaine et autres annexes hors de ce circuit.
A10: cctv | B10: Sécurité / CCTV | C10: crew-06-rook | D10: Revue de vidéosurveillance | E10: 09:00–10:30 | F10: Sol physique, y=624 | G10: Affectation technique conditionnelle | H10: Présence uniquement en phase de travail ; alertes, missions, repos et soins prioritaires. Rondes locales si rail≥70 px ; pas de trajet interannexes.
A11: proving-ground | B11: Proving Ground / Terrain d’essai | C11: crew-02-tamsin-velez | D11: Contrôle du terrain d’essai | E11: 09:00–10:30 | F11: Sol physique, y=624 | G11: Affectation technique conditionnelle | H11: Présence uniquement en phase de travail ; alertes, missions, repos et soins prioritaires. Rondes locales si rail≥70 px ; pas de trajet interannexes.
A12: morgue | B12: Morgue / Autopsie | C12: crew-04-noor-okafor, crew-09-inez-harlow | D12: Soins médico-légaux ; Identification des spécimens | E12: Quart V141 hors rotation ; Quart V141 hors rotation | F12: Sol physique, y=624 | G12: Affectation technique conditionnelle | H12: Présence uniquement en phase de travail ; alertes, missions, repos et soins prioritaires. Rondes locales si rail≥70 px ; pas de trajet interannexes.
A13: escape-pods | B13: Capsules de sauvetage | C13: crew-14-echo-a | D13: Préparation à l’évacuation | E13: 09:00–10:30 | F13: Sol physique, y=624 | G13: Affectation technique conditionnelle | H13: Présence uniquement en phase de travail ; alertes, missions, repos et soins prioritaires. Rondes locales si rail≥70 px ; pas de trajet interannexes.
A14: durandal | B14: Noyau DURANDAL Ω | C14: crew-10-david-8r | D14: Diagnostic informatique | E14: 10:30–12:00 | F14: Sol physique, y=624 | G14: Affectation technique conditionnelle | H14: Présence uniquement en phase de travail ; alertes, missions, repos et soins prioritaires. Rondes locales si rail≥70 px ; pas de trajet interannexes.
A15: bioforge | B15: Accès BIOFORGE isolé | C15: crew-09-inez-harlow | D15: Contrôle des spécimens isolés | E15: 10:30–12:00 | F15: Sol physique, y=624 | G15: Affectation technique conditionnelle | H15: Présence uniquement en phase de travail ; alertes, missions, repos et soins prioritaires. Rondes locales si rail≥70 px ; pas de trajet interannexes.
A16: animal-care | B16: Accueil des compagnons | C16: crew-04-noor-okafor | D16: Inspection du bien-être des compagnons | E16: 09:00–10:30 | F16: Sol physique étendu, y=624 | G16: Affectation technique conditionnelle | H16: Baie de service dégagée ; cycle de visite local et retour au poste. Couchages/enclos conservés ; mission, alerte, repos et soins prioritaires. Pas de trajet interannexes.
... A24: maintenance-spine | B24: Coursive technique traversante | C24: crew-11-jun-park, crew-13-pablo-reyes | D24: Ronde technique ; Contrôle d’isolement | E24: Quart V141 hors rotation ; Quart V141 hors rotation | F24: Sol physique, y=624 | G24: Affectation technique conditionnelle | H24: Présence uniquement en phase de travail ; alertes, missions, repos et soins prioritaires. Rondes locales si rail≥70 px ; pas de trajet interannexes.

Sheet 05_Forge
A1: Tantalus Frontier — V162
A2: 05_Forge
A3: Prépublication : implémentation et validation du commit restent distinctes.
A5: Contrat_ID | B5: Capacité | C5: Borne / condition | D5: État technique | E5: Limite
A6: forge-physical-terminal | B6: Récit sur terminal physique | C6: 64 terminaux par projet ; schema narratif 1 | D6: Implémenté (borné) | E6: Pas de récit sur un calque décoratif, pas de personnage parlant.
A7: forge-acyclic-graph | B7: Pages et réponses liées | C7: 1 à 8 nœuds par terminal ; au plus 2 choix ; graphe sans boucle | D7: Implémenté (borné) | E7: Les pages non liées restent des brouillons, pas une histoire parcourue.
A8: forge-text-limits | B8: Texte éditable | C8: Texte 600 caractères ; titre et réponse 100 | D8: Implémenté (borné) | E8: Textes affichés comme contenu, pas comme code ou balisage exécutable.
A9: forge-objective-condition | B9: Choix conditionné par objectif | C9: Objectif physique existant, y compris dans une autre salle | D9: Implémenté (borné) | E9: Objets de récit et seuil de temps actif V157 suivis séparément ; pas de condition arbitraire ni score libre.
A10: forge-objective-reward | B10: Validation d’un objectif par réponse | C10: Récompense d’objectif idempotente ; pas de boucle condition/récompense | D10: Implémenté (borné) | E10: Les objets de récit ne sont pas des objets de campagne ; aucun crédit ni script arbitraire.
A11: forge-inspector-versioning | B11: Édition, assemblages et versionnement | C11: Inspecteur, annuler/rétablir, JSON schema 3 et versions V136 ; capture, bibliothèque, rotation et pose préservent les références aux objectifs externes. | D11: Implémenté (borné) | E11: La validation du projet reste stricte. L’aperçu et la pose refusent les références absentes, décoratives ou en conflit physique.
A12: forge-native-choice | B12: Choix en playtest Mission / Vaisseau | C12: E choisit une action admissible ; admission commune aux actions et prompts natifs power/archive. Ordre power→archive après visibilité et verrou boss. Réanimation J2, clé et récupération restent déléguées au moteur natif. À la manette, admission avant les actions et arrêt du lot dès l’ouverture d’un récit, pour les deux joueurs. | D12: Implémenté (borné) | E12: Récupération seulement sans terminal en attente admis, sans objectif proche ni porte native cloisonnée ; profil, propriétaire, portée 72 et ligne de vue natifs conservés. Hors Forge : conditions historiques inchangées. Réarmement au neutre ; le refus direct du véhicule précède toute annulation de travail ou d’aperçu.
A13: forge-memory-session | B13: Curseur et historique entre salles | C13: Mémoire entre salles ; checkpoint local explicite séparé, lié au projet et à son équipement. | D13: Implémenté (borné) | E13: Pas de cloud Forge ni écriture des sauvegardes de campagne.
A14: forge-story-items-v157 | B14: Objets de récit nommés | C14: 32 objets uniques/projet ; 16 déclarations/terminal ; exiger, remettre ou consommer l’objet requis. | D14: Implémenté (borné) | E14: Pas d’arme, monnaie, inventaire de campagne ni script libre.
A15: forge-active-time-v157 | B15: Seuil de temps actif | C15: Entier 0–3 600 secondes ; simulation admise seulement, arrêt en pause et récit ouvert. | D15: Implémenté (borné) | E15: Pas d’horloge réelle hors jeu ni minuterie libre de campagne.
A16: forge-local-checkpoint-v157 | B16: Checkpoint local explicite | C16: Un slot ; 4 Mio ; même projet/équipe/équipement/véhicule de départ ; commandes visibles en 16:9/mobile ; focus sur le résumé avant désactivation, puis restauration gardée par moteur/session ; validation avant mutation. | D16: Implémenté (borné) | E16: Pas de cloud, de récompense automatique ni de copie des sauvegardes de campagne.
A17: forge-dialogue-npcs-v158 | B17: PNJ dialoguants éditables | C17: 16 PNJ/salle ; 64 PNJ/projet ; nom 80 caractères ; conduits refusés pour les corps PNJ, arrivées Mission non bloquées par ces conduits. | D17: Implémenté (borné) | E17: PNJ stationnaires de playtest ; pas de membre de campagne, cloud ou script libre.

Sheet 06_Sources
A1: Tantalus Frontier — V162
A2: 06_Sources
A3: Prépublication : implémentation et validation du commit restent distinctes.
A5: Source_ID | B5: Type | C5: Référence | D5: Portée | E5: Limite
A6: SRC-V146 | B6: Plan hérité | C6: docs/forge/xeno-trials/xeno-trials-plan-v146.json | D6: 189 IDs et les 40 présentations des quatre identités. | E6: Préproduction ; aucun kit canonique approuvé.
A7: SRC-V155 | B7: Suivi hérité | C7: docs/forge/xeno-trials/progress-v155.json | D7: 40 présentations et 28 tâches ART153 conservées. | E7: Les cellules de recette prépublication ne prouvent pas la CI.
A8: SRC-NATIVE | B8: Sources natives | C8: src/xeno-trials-rig-data-v154.js | D8: Quatre sprites V154 dont les empreintes sont inchangées. | E8: Ni capture de mouvement,ni dessin de parties cachées.
A9: SRC-AUDITS | B9: Audit technique | C9: docs/forge/V143-AUDIT-FIXES.md | D9: Sauvegardes,cache,commandes et limites restantes | E9: Pas certification des politiques cloud ni du matériel physique.
A10: SRC-POPULATION | B10: Contrats exécutables | C10: src/hub-annex-npc-life-v141.js | D10: 6 affectations initiales +15 rotations ; 19 annexes couvertes conditionnellement. | E10: Aucune nouvelle identité ni trajet continu interannexes.
A11: SRC-FORGE | B11: Contrat exécutable | C11: src/forge-narrative-v156.js | D11: Récits bornés, objets de récit et temps de simulation actif | E11: Pas de script libre ni inventaire de campagne ; checkpoint local suivi séparément.
A12: SRC-CHECKPOINT | B12: Contrat exécutable | C12: src/forge-playtest-checkpoint-v157.js | D12: Codec et checkpoint local explicite liés au projet et à son équipement. | E12: Pas de cloud Forge ni écriture de campagne.
A13: SRC-OPS-ACTIVE | B13: Registre utilisé par l’application | C13: src/special-operations-v131.js | D13: 21 accès jouables : 19 campagnes et 2 surfaces hub ; 20 partiels/1 effectif. | E13: Présence d’une route ne vaut pas campagne ou corpus artistique fini.
A14: SRC-EXIT | B14: Contrat exécutable | C14: src/xeno-trials-sequences-v155.js | D14: Retombée et sortie de rendu V157 séparées des 40 séquences/200 clés héritées ; identités de partie/tick autonomes. | E14: Quatre rigs natifs ; pas de locomotion complète ni certification 1:1.
A15: SRC-SUCCESSION | B15: Pont de vérification | C15: scripts/audit-succession-v157.mjs | D15: Documents V156 ancrés ; chaque transition old/new SHA et chaque source courante vérifiés. | E15: Pas de comparaison à des commits absents en CI shallow.
A16: SRC-NPCS-V158 | B16: Contrat exécutable | C16: src/forge-npcs-v158.js | D16: PNJ et récits éditables bornés dans les playtests Forge. | E16: Archive sandbox ancienne absente ; pas de cloud ni script libre.
... A34: C162-APC | B34: Périmètre hors Forge / demande existante | C34: src/campaign-convoy-history-v162.js ; src/campaign-convoy-history-ui-v162.js ; campaign-convoy-history-v162.css ; scripts/qa-campaign-convoy-history-v162.py | D34: Une archive compacte conserve au plus huit résultats APC natifs distincts, avec leurs relevés de distance, barrages, reine, blindage réel, protocole et trois lectures validées. L’admission exige le même identifiant d’opération, campagne, monde, numéro de résolution, déploiement et état terminal ; le succès exige son reçu complet, et l’échec ne conserve que le checkpoint partiel réel clairement désigné. L’identité V84 de l’opérateur est figée lorsqu’elle est valide ; les anciens retours peuvent rester anonymes. La consultation est en lecture seule et ne verse aucune récompense. | E34: Journal de huit retours au plus, pas campagne étendue, enregistrement vidéo ou nouveau canon. Seuls les vrais résultats admissibles sont capturés ; aucun résultat absent n’est inventé et la lecture ne rejoue pas de paiement.

Sheet 07_Recette
A1: Tantalus Frontier — V162
A2: 07_Recette
A3: Prépublication : implémentation et validation du commit restent distinctes.
A5: Contrôle_ID | B5: Commande / contrôle | C5: État prépublication | D5: Portée / limite
A6: QA162-NODE | B6: Suites Node déclarées et dédupliquées | C6: À exécuter sur le commit final | D6: Aucun total de recette V161 transféré.
A7: QA162-HARPOON | B7: scripts/verify-harpoon-unload-v162.mjs ; scripts/verify-weapon-actions-v131.mjs ; scripts/qa-harpoon-native-v162.py | C7: À exécuter sur le commit final | D7: Le défaut de fermeture et le vieux blocage d’achat V61 sont deux constats distincts. Aucun nouveau module d’arme, dessin ou source canonique. La recette des quatre variantes sur le commit final reste à exécuter ; les parcours initiaux ne sont pas transférés comme résultats finaux.
A8: QA162-AUDIO | B8: scripts/verify-audio-lifecycle-v162.mjs ; scripts/qa-audio-native-v162.py | C8: À exécuter sur le commit final | D8: Aucune nouvelle musique, voix, banque originale ou source de franchise. Le pilote Chromium headless active réellement un autre onglet et minimise la fenêtre, mais document.hidden n’y est pas observé : aucun parcours de scène masquée réussi n’est certifié. Un contrôle automatisé ne certifie pas le rendu sur haut-parleurs ou appareils physiques ; recette exacte à exécuter.
A9: QA162-CREW | B9: scripts/verify-npc-medical-route-v162.mjs ; scripts/qa-npc-medical-route-v162.py | C9: À exécuter sur le commit final | D9: Un circuit parent/annexe borné. Aucun ascenseur, déplacement physique entre ponts, nouveau dessin ou cycle de dos. Les soins, missions et autres priorités restent natifs ; le trajet après délégation n’est pas prouvé par ce lot.
A10: QA162-APC | B10: scripts/verify-campaign-convoy-history-v162.mjs ; scripts/qa-campaign-convoy-history-v162.py | C10: À exécuter sur le commit final | D10: Journal de huit retours au plus, pas campagne étendue, enregistrement vidéo ou nouveau canon. Seuls les vrais résultats admissibles sont capturés ; aucun résultat absent n’est inventé et la lecture ne rejoue pas de paiement.
A11: QA162-DOCUMENTS | B11: node --test scripts/verify-audit-continuation-v162.mjs | C11: À exécuter sur le commit final | D11: 68 tâches Trials, 189 identités, 16 classeurs historiques et Forge explicitement reportée.
A12: QA162-NATIVE | B12: Contrôles natifs, import Save déclaré et rechargements réels | C12: À vérifier séparément | D12: Recettes automatisées ; aucun participant humain ou contenu artistique 1:1 déclaré.
A13: QA162-RELEASE | B13: Paquet, CI, revue, fusion et publication | C13: À vérifier séparément | D13: Les résultats seront liés à leurs reçus réels, sans modifier les sources prépublication.

Sheet 08_Roster
A1: Tantalus Frontier — V162
A2: 08_Roster
A3: Prépublication : implémentation et validation du commit restent distinctes.
A5: ID exact | B5: Identité | C5: Famille | D5: Rig V154 | E5: Séquences V155 | F5: Fidélité approuvée
A6: warrior | B6: Warrior | C6: xenomorph | D6: 0 | E6: 0 | F6: 0
A7: runner | B7: Runner | C7: xenomorph | D7: 0 | E7: 0 | F7: 0
A8: arachnoid | B8: Arachnoid | C8: xenomorph | D8: 0 | E8: 0 | F8: 0
A9: defender | B9: Defender | C9: xenomorph | D9: 0 | E9: 0 | F9: 0
A10: grid | B10: Grid | C10: xenomorph | D10: 0 | E10: 0 | F10: 0
A11: spitter | B11: Spitter | C11: xenomorph | D11: 0 | E11: 0 | F11: 0
A12: prowler | B12: Prowler | C12: xenomorph | D12: 1 | E12: 10 | F12: 0
A13: razor-claws | B13: Razor Claws | C13: xenomorph | D13: 0 | E13: 0 | F13: 0
A14: chrysalis | B14: Chrysalis | C14: xenomorph | D14: 0 | E14: 0 | F14: 0
A15: smasher | B15: Smasher | C15: xenomorph | D15: 0 | E15: 0 | F15: 0
A16: predalien | B16: Predalien — Primal Hunt | C16: xenomorph | D16: 0 | E16: 0 | F16: 0
A17: xenoborg | B17: Xenoborg | C17: xenomorph | D17: 0 | E17: 0 | F17: 0
... A194: drive-v123-game-combat-synthetic-avp2 | B194: Combat Synthetic — unité désarmée — Altered | C194: synthetic | D194: 0 | E194: 0 | F194: 0

Sheet 09_AutresAudits
A1: Tantalus Frontier — V162
A2: 09_AutresAudits
A3: Prépublication : implémentation et validation du commit restent distinctes.
A5: Manque_ID | B5: Source | C5: État historique V156 | D5: État / dépendance V159 | E5: Clôture artistique
A6: encyclopedia-source | B6: Pont Excel V61/V63 et catalogue courant V62 ; audit V61 historique | C6: Source brute absente | D6: Classeur brut absent ; métadonnées du pont présentes (2363 entités globales, 2929 thématiques), 14 liens d’armes/3 de véhicules et catalogue jeu de 1329 entrées disponibles. Pas de revue du classeur brut. | E6: 0
A7: dlc-v10-archives | B7: Conversations de reprise | C7: Archives absentes | D7: DLC Blackout/Earth et sprites V10 non récupérés. | E7: 0
A8: trials-185-other | B8: Plan V146 / suivi V155 | C8: 185 IDs sans rigsV154/séquencesV155 | D8: Leurs mécaniques existantes restent distinctes de ce lot. | E8: 0
A9: trials-full-locomotion | B9: Suivis V148-V155 | C9: Ouvert | D9: Locomotion/combat/finishes/dessins complets restent à produire. | E9: 0
A10: forge-script-free | B10: Audit Forge | C10: Ouvert | D10: Les récits à terminaux ne constituent pas un langage de script libre. | E10: 0
A11: forge-cloud-progress | B11: Audit Forge | C11: Ouvert | D11: Checkpoint local explicite livré techniquement ; cloud Forge toujours ouvert. | E11: 0
A12: operations-active-registry | B12: SPECIAL_OPERATIONS_V131 | C12: V67 : 13 sans route | D12: V131 déjà actif : 21 accès jouables,20 partiels/1 effectif ; corpus et campagnes étendues restent ouverts. | E12: 0
A13: annex-interroom-travel | B13: Planning équipage | C13: 18 annexes ; pas de marche interannexes | D13: 19 affectations historiques ; premier circuit parent-annexe BISHOP laboratoire/baie synthétique ajouté V159. Autres routes, quarantaine, ponts et ascenseurs restent ouverts. | E13: 0
A14: costume-atlases | B14: Registre franchise V119 | C14: 30 sans atlas dédié | D14: Atlas et animations dédiés restent distincts du kit colonial modulaire existant. | E14: 0

Sheet 10_Operations
A1: Tantalus Frontier — V162
A2: 10_Operations
A3: Prépublication : implémentation et validation du commit restent distinctes.
A5: Opération_ID | B5: Titre | C5: Surface / route | D5: Statut technique | E5: Jouable | F5: Mécaniques / corpus restants | G5: Canon exact
A6: queen-mother-song | B6: LE CHANT DE LA REINE-MÈRE | C6: special-queen-mother-v131 | D6: partial | E6: 1 | F6: dedicated-queen-mother-animation; complete-royal-cast | G6: 0
A7: hive-world | B7: LV-XENO : LA RUCHE-MONDE | C7: special-hive-world-v131 | D7: partial | E7: 1 | F7: dedicated-planet-queen-art; complete-organ-biomes | G7: 0
A8: titan-equalizer | B8: TALOS CONTRE LE TITAN | C8: special-titan-v131 | D8: partial | E8: 1 | F8: dedicated-talos-titan-art; canonical-mega-loader-corpus | G8: 0
A9: narrative-collectables | B9: ARCHIVES NARRATIVES ÉTENDUES | C9: special-narrative-qz17 | D9: partial | E9: 1 | G9: 0
A10: alpha-bravo-coop | B10: DOCTRINE ALPHA / BRAVO | C10: special-alpha-bravo-doctrine | D10: partial | E10: 1 | G10: 0
A11: eloise-uncrowned-queen | B11: ÉLOÏSE : LA REINE SANS COURONNE | C11: special-eloise-v131 | D11: partial | E11: 1 | F11: dedicated-eloise-animation; hush-six-and-mother-hunter-art | G11: 0
A12: pangaea-second-extinction | B12: PANGAEA : LA SECONDE EXTINCTION | C12: special-pangaea-v131 | D12: partial | E12: 1 | F12: dedicated-dinosaur-and-sauria-art; complete-prehistoric-corpus | G12: 0
A13: atax-false-queen | B13: A.T.A.X.-Q : LA FAUSSE REINE | C13: special-atax-v131 | D13: partial | E13: 1 | F13: dedicated-regina-animation; complete-seven-sector-campaign | G13: 0
A14: alien-survival-systems | B14: SYSTÈMES DE SURVIE ALIEN | C14: special-alien-survival-systems | D14: effective | E14: 1 | G14: 0
A15: jeri-false-son | B15: JERI : LE FAUX FILS | C15: special-jeri-v131 | D15: partial | E15: 1 | F15: dedicated-jeri-and-saint-animation; complete-segmented-synthetic-art | G15: 0
A16: black-abyss | B16: OPÉRATION ABYSSE NOIR | C16: special-black-abyss-v131 | D16: partial | E16: 1 | F16: dedicated-hadal-manta-art; complete-aquatic-bestiary | G16: 0
A17: tantalus-hub-expansion | B17: USS TANTALUS — HUB COMMERCIAL | C17: hub | D17: partial | E17: 1 | F17: independent-prop-bitmaps; dedicated-annex-npcs; physical-training-exercises; physical-archive-replay; cctv-lockdown-controls | G17: 0
A18: bioforge | B18: BIOFORGE | C18: hub | D18: partial | E18: 1 | F18: full-enemy-roster; complete-dedicated-art-corpus | G18: 0
A19: protocol-z110 | B19: PROTOCOLE Z-110 | C19: special-z110-v131 | D19: partial | E19: 1 | F19: dedicated-z110-and-morrigan-art; complete-mecha-animation-corpus | G19: 0
A20: mire-archive-001 | B20: MIRE ARCHIVE 001 : NOSTROMO | C20: special-nostromo-v131 | D20: partial | E20: 1 | F20: complete-nostromo-cast; complete-historical-campaign | G20: 0
A21: broodstorm | B21: BROODSTORM | C21: special-broodstorm-v131 | D21: partial | E21: 1 | F21: dedicated-flying-queen-art; complete-modular-dropship-corpus | G21: 0
A22: black-cocoon | B22: COCON NOIR | C22: special-black-cocoon | D22: partial | E22: 1 | F22: dedicated-cocoon-bitmap-corpus; extended-survivor-campaign | G22: 0
A23: last-course-tantalus | B23: LA DERNIÈRE COURSE DE TANTALUS | C23: special-apc-convoy | D23: partial | E23: 1 | F23: local-convoy-coop | G23: 0
A24: cargo-brutal | B24: CARGO BRUTAL | C24: special-cargo-brutal | D24: partial | E24: 1 | F24: dedicated-cargo-matriarch-art | G24: 0
A25: c12-horde | B25: SAS C-12 · DÉFENSE | C25: special-c12-horde | D25: partial | E25: 1 | F25: extended-horde-campaign | G25: 0
A26: archive-relay | B26: ARCHIVES QZ-18 · RELAIS | C26: special-archive-relay | D26: partial | E26: 1 | F26: recorded-media-corpus | G26: 0

Sheet 11_Succession
A1: Tantalus Frontier — V162
A2: 11_Succession
A3: Prépublication : implémentation et validation du commit restent distinctes.
A5: Module | B5: SHA V158 | C5: SHA V159 | D5: Évolution volontaire | E5: Vérificateurs comportementaux
A6: index.html | B6: 84f22fb623d4d7bf5db5b2b55e9da70516ffc09ac0eacaad904b0cbd74bc240a | C6: 9cce9373641e8440201bf6d64cd5b48ae0dfcab7f7cc90c5fe6230e9d2c500e0 | D6: Charge la présentation dédiée du journal compact des retours APC depuis une feuille locale admise, en gardant les autres contrôles natifs et le déploiement inchangés. | E6: scripts/verify-campaign-convoy-history-v162.mjs ; scripts/verify-audit-v143.mjs
A7: src/app.js | B7: c4a2f8e5d5b9246c97fe9c9e357ce834c61307a609e0626565cff8f47cf80c5c | C7: ac0404430bb38a08b454bcc30a4d85a6af1f0afb57a953552739039cdc8180dd | D7: Capture le checkpoint de mission avant stop lors de la fermeture puis raccorde le service médical et l’archive compacte APC, sans modifier les modules Forge reportés. | E7: scripts/verify-harpoon-unload-v162.mjs ; scripts/verify-weapon-actions-v131.mjs ; scripts/verify-audio-lifecycle-v162.mjs ; scripts/verify-npc-medical-route-v162.mjs ; scripts/verify-campaign-convoy-history-v162.mjs
A8: src/npc-service-routes-v161.js | B8: 1571979e0dfe7d6bbad7e120aa1edae445099911909da0e7e3748e514674e189 | C8: 3bfd466c91a0861b1f99c806769a69a144942627c25fe2f1d47dcbd40711bf56 | D8: Expose la fabrique de circuits de service paramétrée et intègre le circuit médical indépendant, en préservant les propriétaires existants et les priorités natives. | E8: scripts/verify-npc-medical-route-v162.mjs
A9: src/save.js | B9: 59d429c858402a26a7768e47e6520aff95f6b6f12668f8bb69430502c8952e5d | C9: 98a20e4a0f52a7c33d5d3e53757ad4aba30cad350bacbe2fbac4aa8a6dc3403a | D9: Normalise la progression bornée du service médical et les huit comptes rendus APC admissibles en conservant les autres données natives et les schémas historiques. | E9: scripts/verify-npc-medical-route-v162.mjs ; scripts/verify-campaign-convoy-history-v162.mjs
A10: sw.js | B10: fd43d5989bde6df59643796d7a9c23fbfaa3e444bb07967f6d90b8cfba40b76d | C10: 0b506c1e7e57e36e50348d3a89400cc5976a65202b8830ef2163f9cde0c2e657 | D10: Admet les nouveaux modules et la feuille de présentation hors Forge dans le shell local avec un cache de continuation distinct, sans modifier les modules Forge reportés. | E10: scripts/verify-audit-v143.mjs ; scripts/verify-npc-medical-route-v162.mjs ; scripts/verify-campaign-convoy-history-v162.mjs
A11: campaign-convoy-history-v162.css | B11: Non épinglé en V161 | C11: 6f92b205b5c1970912e1051be0b6d6c3b2716acf27e767423a8d9c25b93806e2 | D11: Une archive compacte conserve au plus huit résultats APC natifs distincts, avec leurs relevés de distance, barrages, reine, blindage réel, protocole et trois lectures validées. L’admission exige le même identifiant d’opération, campagne, monde, numéro de résolution, déploiement et état terminal ; le succès exige son reçu complet, et l’échec ne conserve que le checkpoint partiel réel clairement désigné. L’identité V84 de l’opérateur est figée lorsqu’elle est valide ; les anciens retours peuvent rester anonymes. La consultation est en lecture seule et ne verse aucune récompense. | E11: scripts/verify-campaign-convoy-history-v162.mjs
A12: src/audio.js | B12: Non épinglé en V161 | C12: ce43a728dc9cc14a7f0b1b0226163c5434fdf1eb804e349a427abdaeeac0b5c2 | D12: Ajoute la garde de volume maître nul aux chemins d’effets décodés et de synthèse pour refuser toute admission sonore pendant la coupure, sans changer les médias ou mécanismes de transfert hérités. | E12: scripts/verify-audio-lifecycle-v162.mjs
A13: src/campaign-convoy-history-ui-v162.js | B13: Non épinglé en V161 | C13: e973c53c63ef8b425772ad049cab133b7052532be6956210e149174b3d940619 | D13: Une archive compacte conserve au plus huit résultats APC natifs distincts, avec leurs relevés de distance, barrages, reine, blindage réel, protocole et trois lectures validées. L’admission exige le même identifiant d’opération, campagne, monde, numéro de résolution, déploiement et état terminal ; le succès exige son reçu complet, et l’échec ne conserve que le checkpoint partiel réel clairement désigné. L’identité V84 de l’opérateur est figée lorsqu’elle est valide ; les anciens retours peuvent rester anonymes. La consultation est en lecture seule et ne verse aucune récompense. | E13: scripts/verify-campaign-convoy-history-v162.mjs
A14: src/campaign-convoy-history-v162.js | B14: Non épinglé en V161 | C14: 30acb584825844a348e37436b74fbb956e76a1ae7d2e4c1bb662587fec3fba31 | D14: Une archive compacte conserve au plus huit résultats APC natifs distincts, avec leurs relevés de distance, barrages, reine, blindage réel, protocole et trois lectures validées. L’admission exige le même identifiant d’opération, campagne, monde, numéro de résolution, déploiement et état terminal ; le succès exige son reçu complet, et l’échec ne conserve que le checkpoint partiel réel clairement désigné. L’identité V84 de l’opérateur est figée lorsqu’elle est valide ; les anciens retours peuvent rester anonymes. La consultation est en lecture seule et ne verse aucune récompense. | E14: scripts/verify-campaign-convoy-history-v162.mjs
A15: src/npc-medical-route-v162.js | B15: Non épinglé en V161 | C15: 389b2afae1898c6f6b675d9ebac116c936ce2e90c26fd5d09bbd94e39f00caa6 | D15: Expose la fabrique de circuits de service paramétrée et intègre le circuit médical indépendant, en préservant les propriétaires existants et les priorités natives. | E15: scripts/verify-npc-medical-route-v162.mjs

Sheet 12_TrialsSortie
A1: Tantalus Frontier — V162
A2: 12_TrialsSortie
A3: Prépublication : implémentation et validation du commit restent distinctes.
A5: Fighter_ID | B5: Contrat | C5: Déclenchement | D5: Déplacement | E5: Portée / limite | F5: État artistique | G5: Clôture | H5: Approuvé 1:1
A6: prowler | B6: native-spatial-exit-v157 | C6: Après phases de verdict admissibles ou retombée V157 autonome | D6: Retombée de rendu 180–600 ms si aérien ; puis trajet vers bord et appuis alternés | E6: Rig natif admis seulement ; corps physiques inchangés ; caméra fixe et appuis contrôlés ; pas de marche dessinée complète. Pause/skip/mouvement réduit respectés. | F6: Partiel | G6: 0 | H6: 0
A7: dd-darwin-era-cultist | B7: native-spatial-exit-v157 | C7: Après phases de verdict admissibles ou retombée V157 autonome | D7: Retombée de rendu 180–600 ms si aérien ; puis trajet vers bord et appuis alternés | E7: Rig natif admis seulement ; corps physiques inchangés ; caméra fixe et appuis contrôlés ; pas de marche dessinée complète. Pause/skip/mouvement réduit respectés. | F7: Partiel | G7: 0 | H7: 0
A8: import-game-dd-wy-commando | B8: native-spatial-exit-v157 | C8: Après phases de verdict admissibles ou retombée V157 autonome | D8: Retombée de rendu 180–600 ms si aérien ; puis trajet vers bord et appuis alternés | E8: Rig natif admis seulement ; corps physiques inchangés ; caméra fixe et appuis contrôlés ; pas de marche dessinée complète. Pause/skip/mouvement réduit respectés. | F8: Partiel | G8: 0 | H8: 0
A9: import-game-dd-guardian | B9: native-spatial-exit-v157 | C9: Après phases de verdict admissibles ou retombée V157 autonome | D9: Retombée de rendu 180–600 ms si aérien ; puis trajet vers bord et appuis alternés | E9: Rig natif admis seulement ; corps physiques inchangés ; caméra fixe et appuis contrôlés ; pas de marche dessinée complète. Pause/skip/mouvement réduit respectés. | F9: Partiel | G9: 0 | H9: 0

Sheet 13_Preuve1to1
A1: Tantalus Frontier — V162
A2: 13_Preuve1to1
A3: Prépublication : implémentation et validation du commit restent distinctes.
A5: ID exact | B5: Identité | C5: Œuvre déclarée | D5: Sources héritées | E5: Image du projet | F5: SHA image projet | G5: Édition œuvre fixée | H5: Timecode / page œuvre | I5: Capture œuvre approuvée | J5: Fidélité au projet — portée | K5: Œuvre approuvée 1:1 | L5: Preuve manquante
A6: warrior | B6: Warrior | C6: Aliens (1986) | D6: S01 | J6: Non évalué dans ce lot | K6: 0 | L6: Édition/build, métrage ou page et capture approuvée de l’œuvre non relevés.
A7: runner | B7: Runner | C7: Alien 3 (1992) | D7: S02 | J7: Non évalué dans ce lot | K7: 0 | L7: Édition/build, métrage ou page et capture approuvée de l’œuvre non relevés.
A8: arachnoid | B8: Arachnoid | C8: Alien vs. Predator — Capcom (1994) | D8: S16 | J8: Non évalué dans ce lot | K8: 0 | L8: Édition/build, métrage ou page et capture approuvée de l’œuvre non relevés.
A9: defender | B9: Defender | C9: Alien vs. Predator — Capcom (1994) | D9: R01 | J9: Non évalué dans ce lot | K9: 0 | L9: Édition/build, métrage ou page et capture approuvée de l’œuvre non relevés.
A10: grid | B10: Grid | C10: Alien vs. Predator (2004) | D10: R01 | J10: Non évalué dans ce lot | K10: 0 | L10: Édition/build, métrage ou page et capture approuvée de l’œuvre non relevés.
A11: spitter | B11: Spitter | C11: Aliens: Colonial Marines (2013) | D11: R01 | J11: Non évalué dans ce lot | K11: 0 | L11: Édition/build, métrage ou page et capture approuvée de l’œuvre non relevés.
A12: prowler | B12: Prowler | C12: Aliens: Fireteam Elite (2021) | D12: S08 | E12: /assets/user/castes-v87/game_afe_prowler.png | F12: 48edd1af2710048a065433b9e2c8dc20a03b05bc0a46a47394704f3a0c8bd544 | J12: Image du projet conservée ; geste adapté | K12: 0 | L12: Édition/build, métrage ou page et capture approuvée de l’œuvre non relevés.
A13: razor-claws | B13: Razor Claws | C13: Alien vs. Predator — Capcom (1994) | D13: S16 | J13: Non évalué dans ce lot | K13: 0 | L13: Édition/build, métrage ou page et capture approuvée de l’œuvre non relevés.
A14: chrysalis | B14: Chrysalis | C14: Alien vs. Predator — Capcom (1994) | D14: S16 | J14: Non évalué dans ce lot | K14: 0 | L14: Édition/build, métrage ou page et capture approuvée de l’œuvre non relevés.
A15: smasher | B15: Smasher | C15: Alien vs. Predator — Capcom (1994) | D15: R01 | J15: Non évalué dans ce lot | K15: 0 | L15: Édition/build, métrage ou page et capture approuvée de l’œuvre non relevés.
A16: predalien | B16: Predalien — Primal Hunt | C16: Aliens versus Predator 2: Primal Hunt (2002) | D16: R01 | J16: Non évalué dans ce lot | K16: 0 | L16: Édition/build, métrage ou page et capture approuvée de l’œuvre non relevés.
A17: xenoborg | B17: Xenoborg | C17: Aliens versus Predator (1999) | D17: S12 | J17: Non évalué dans ce lot | K17: 0 | L17: Édition/build, métrage ou page et capture approuvée de l’œuvre non relevés.
A18: royal-guard | B18: Royal Guard | C18: Alien vs. Predator — Capcom (1994) | D18: R01 | J18: Non évalué dans ce lot | K18: 0 | L18: Édition/build, métrage ou page et capture approuvée de l’œuvre non relevés.
A19: queen | B19: Reine mobile | C19: Aliens (1986) | D19: S01 | J19: Non évalué dans ce lot | K19: 0 | L19: Édition/build, métrage ou page et capture approuvée de l’œuvre non relevés.
A20: ravager | B20: Ravager | C20: Aliens vs. Predator: Extinction (2003) | D20: R01 | J20: Non évalué dans ce lot | K20: 0 | L20: Édition/build, métrage ou page et capture approuvée de l’œuvre non relevés.
A21: crusher-acm | B21: Crusher — ACM | C21: Aliens: Colonial Marines (2013) | D21: R01 | J21: Non évalué dans ce lot | K21: 0 | L21: Édition/build, métrage ou page et capture approuvée de l’œuvre non relevés.
A22: boiler | B22: Boiler | C22: Aliens: Colonial Marines (2013) | D22: R01 | J22: Non évalué dans ce lot | K22: 0 | L22: Édition/build, métrage ou page et capture approuvée de l’œuvre non relevés.
A23: burster | B23: Burster | C23: Aliens: Fireteam Elite (2021) | D23: S08 | J23: Non évalué dans ce lot | K23: 0 | L23: Édition/build, métrage ou page et capture approuvée de l’œuvre non relevés.
A24: stalker-arcade | B24: Stalker — arcade | C24: Alien vs. Predator — Capcom (1994) | D24: R01 | J24: Non évalué dans ce lot | K24: 0 | L24: Édition/build, métrage ou page et capture approuvée de l’œuvre non relevés.
... A148: import-game-afe2-bulwark | B148: Bulwark — adaptation | C148: Aliens: Fireteam Elite 2 (2026), build à relever | D148: S10 | J148: Non évalué dans ce lot | K148: 0 | L148: Édition/build, métrage ou page et capture approuvée de l’œuvre non relevés.
A149: import-game-dd-wy-commando | B149: Weyland-Yutani Commando — Altered — adaptation | C149: Aliens: Dark Descent (2023) | D149: R01 | E149: /assets/openai/sprites/static-game-v106/game-dd-wy-commando.png | F149: 1bcafd4c6b5e06611d0184c317f76422749d43e4b97a14f39316eef3eca3c012 | J149: Image du projet conservée ; geste adapté | K149: 0 | L149: Édition/build, métrage ou page et capture approuvée de l’œuvre non relevés.
A150: import-game-afe2-exploder | B150: Exploder — adaptation | C150: Aliens: Fireteam Elite 2 (2026), build à relever | D150: S11 | J150: Non évalué dans ce lot | K150: 0 | L150: Édition/build, métrage ou page et capture approuvée de l’œuvre non relevés.
A151: import-game-afe2-harbinger | B151: Harbinger — adaptation | C151: Aliens: Fireteam Elite 2 (2026), build à relever | D151: S11 | J151: Non évalué dans ce lot | K151: 0 | L151: Édition/build, métrage ou page et capture approuvée de l’œuvre non relevés.
A152: import-game-dd-synthetic | B152: Synthetic — adaptation | C152: Aliens: Dark Descent (2023) | D152: R01 | J152: Non évalué dans ce lot | K152: 0 | L152: Édition/build, métrage ou page et capture approuvée de l’œuvre non relevés.
A153: import-game-dd-guardian | B153: Guardian — Darwin Era — adaptation | C153: Aliens: Dark Descent (2023) | D153: R01 | E153: /assets/openai/sprites/static-game-v106/game-dd-guardian.png | F153: 9c78992ce49b080c73fef68a9813a1717970b5dae4be4e03d409a9876169d1c8 | J153: Image du projet conservée ; geste adapté | K153: 0 | L153: Édition/build, métrage ou page et capture approuvée de l’œuvre non relevés.
A154: synth-incinerator | B154: Synth Incinerator | C154: Aliens: Fireteam Elite (2021) | D154: S08, R03 | J154: Non évalué dans ce lot | K154: 0 | L154: Édition/build, métrage ou page et capture approuvée de l’œuvre non relevés.
A155: synth-detonator | B155: Synth Detonator | C155: Aliens: Fireteam Elite (2021) | D155: S08, R03 | J155: Non évalué dans ce lot | K155: 0 | L155: Édition/build, métrage ou page et capture approuvée de l’œuvre non relevés.
A156: synth-containment | B156: Synth Containment | C156: Aliens: Fireteam Elite (2021) | D156: S08, R03 | J156: Non évalué dans ce lot | K156: 0 | L156: Édition/build, métrage ou page et capture approuvée de l’œuvre non relevés.
A157: synth-enforcer | B157: Synth Enforcer | C157: Aliens: Fireteam Elite (2021) | D157: S08, R03 | J157: Non évalué dans ce lot | K157: 0 | L157: Édition/build, métrage ou page et capture approuvée de l’œuvre non relevés.
A158: afe2-engineer-hybrid | B158: Engineer hybrid — adaptation | C158: Aliens: Fireteam Elite 2 (2026), build à relever | D158: S11 | J158: Non évalué dans ce lot | K158: 0 | L158: Édition/build, métrage ou page et capture approuvée de l’œuvre non relevés.
A159: synth-peacekeeper | B159: Peacekeeper — adaptation | C159: Aliens: Fireteam Elite 2 (2026), build à relever | D159: S10 | J159: Non évalué dans ce lot | K159: 0 | L159: Édition/build, métrage ou page et capture approuvée de l’œuvre non relevés.
A160: afe2-spider | B160: Spider — adaptation | C160: Aliens: Fireteam Elite 2 (2026), build à relever | D160: S10 | J160: Non évalué dans ce lot | K160: 0 | L160: Édition/build, métrage ou page et capture approuvée de l’œuvre non relevés.
A161: afe2-igniter | B161: Igniter — interprétation | C161: Aliens: Fireteam Elite 2 (2026), build à relever | D161: S10 | J161: Non évalué dans ce lot | K161: 0 | L161: Édition/build, métrage ou page et capture approuvée de l’œuvre non relevés.
A162: afe2-bombardier | B162: Bombardier — interprétation | C162: Aliens: Fireteam Elite 2 (2026), build à relever | D162: S10 | J162: Non évalué dans ce lot | K162: 0 | L162: Édition/build, métrage ou page et capture approuvée de l’œuvre non relevés.
A163: afe2-huntsman | B163: Huntsman — interprétation | C163: Aliens: Fireteam Elite 2 (2026), build à relever | D163: S10 | J163: Non évalué dans ce lot | K163: 0 | L163: Édition/build, métrage ou page et capture approuvée de l’œuvre non relevés.
A164: import-xeno-titan-queen-nolegs | B164: Titan Queen NoLegs — reconstruction | C164: Pack 270926 — silhouette inférieure reconstruite pour la simulation | D164: R01 | J164: Non évalué dans ce lot | K164: 0 | L164: Édition/build, métrage ou page et capture approuvée de l’œuvre non relevés.
...

Sheet 14_References
A1: Tantalus Frontier — V162
A2: 14_References
A3: Prépublication : implémentation et validation du commit restent distinctes.
A5: Source_ID | B5: Titre | C5: Nature | D5: État de consultation | E5: Consulté le | F5: Ce que la source établit | G5: Ce qu’elle ne prouve pas | H5: Repère | I5: URL
A6: R01 | B6: Roster et arènes du dépôt | C6: Code du projet | D6: Consultée | E6: 2026-10-16 | F6: IDs, variantes, origine déclarée, six arènes | G6: Un champ sourceWork ne prouve pas la fidélité d’un dessin. | H6: XENO_TRIALS_FIGHTERS_V96; XENO_TRIALS_STAGES_V96 | I6: https://github.com/darknigthmare/aliens-tantalus-frontier/blob/39bc11e5abe4427ae44c452e9727288e63310ec3/src/xeno-trials-data-v96.js
A7: R02 | B7: Moteur de duel | C7: Code du projet | D7: Consultée | E7: 2026-10-16 | F7: Attaques légères/lourdes/spéciales; rounds; simulation 120 Hz | G7: Les statistiques sont celles du projet, pas celles des films. | H7: XENO_TRIALS_ATTACKS_V96; finishRound; nextXenoTrialsRoundV96 | I7: https://github.com/darknigthmare/aliens-tantalus-frontier/blob/39bc11e5abe4427ae44c452e9727288e63310ec3/src/xeno-trials-engine-v96.js
A8: R03 | B8: Contrats synthétiques | C8: Code du projet | D8: Consultée | E8: 2026-10-16 | F8: Flammes, détonation, bouclier | G8: Ne confère pas automatiquement ces pouvoirs à tous les synthétiques. | H8: SYNTH_TRIAL_ATTACKS_V110 | I8: https://github.com/darknigthmare/aliens-tantalus-frontier/blob/39bc11e5abe4427ae44c452e9727288e63310ec3/src/synth-combat-v110.js
A9: R04 | B9: Échelles de présentation | C9: Code du projet | D9: Consultée | E9: 2026-10-16 | F9: Échelles et pivots existants | G9: Estimations du projet; tailles canoniques non certifiées. | H9: getXenoTrialsPhysicalScaleV119 | I9: https://github.com/darknigthmare/aliens-tantalus-frontier/blob/39bc11e5abe4427ae44c452e9727288e63310ec3/src/xeno-trials-physical-scale-v119.js
A10: S01 | B10: Aliens — fiche du distributeur | C10: Distributeur officiel | D10: Consultée | E10: 2026-10-16 | F10: Œuvre et référence filmique | G10: Ne documente pas un moveset ni les minutages des gestes. | H10: Texte public; métrage détaillé non relevé | I10: https://www.20thcenturystudios.com/movies/aliens
A11: S02 | B11: Alien 3 — fiche du distributeur | C11: Distributeur officiel | D11: Consultée | E11: 2026-10-16 | F11: Œuvre de référence du Runner | G11: Choisir version cinéma ou Assembly Cut; métrage non relevé. | H11: Texte public; métrage détaillé non relevé | I11: https://www.20thcenturystudios.com/movies/alien-3
A12: S03 | B12: Alien Resurrection — fiche du distributeur | C12: Distributeur officiel | D12: Consultée | E12: 2026-10-16 | F12: Œuvre de référence Newborn/Auriga | G12: Ne valide pas chaque coup proposé. | H12: Texte public; métrage détaillé non relevé | I12: https://www.20thcenturystudios.com/movies/alien-resurrection
A13: S04 | B13: Prometheus — fiche du distributeur | C13: Distributeur officiel | D13: Consultée | E13: 2026-10-16 | F13: Référence des Ingénieurs | G13: Ne certifie pas les tenues utilisateur ni un arsenal universel. | H13: Texte public; métrage détaillé non relevé | I13: https://www.20thcenturystudios.com/movies/prometheus
A14: S05 | B14: Alien Covenant — fiche du distributeur | C14: Distributeur officiel | D14: Consultée | E14: 2026-10-16 | F14: Œuvre de référence de David | G14: Chorégraphie et tenue à relever dans l’édition retenue. | H14: Texte public; métrage détaillé non relevé | I14: https://www.20thcenturystudios.com/movies/alien-covenant
A15: S06 | B15: Alien Romulus — fiche du distributeur | C15: Distributeur officiel | D15: Consultée | E15: 2026-10-16 | F15: Œuvre de référence Offspring | G15: Ne certifie ni durée des attaques ni locomotion de l’asset Altered. | H15: Texte public; métrage détaillé non relevé | I15: https://www.20thcenturystudios.com/movies/alien-romulus
A16: S07 | B16: Alien Isolation — manuel Feral | C16: Manuel officiel | D16: Consultée | E16: 2026-10-16 | F16: Commandes, Sevastopol, outils de survie | G16: Pas un catalogue exhaustif des animations Working Joe. | H16: Texte public; métrage détaillé non relevé | I16: https://www.feralinteractive.com/en/manuals/alienisolation/latest/steam/
... A70: H41 | B70: Référence héritée — Cultiste Darwin Era | C70: Référence héritée | D70: À vérifier | E70: 2026-10-16 | F70: dd-darwin-era-cultist | G70: Non consultée dans cette passe; ne pas promouvoir en preuve. | H70: Repris du registre du dépôt | I70: https://magazine.artstation.com/2023/07/tindalos-interactive-aliens-dark-descent-art-blast/

Sheet 15_LotsV159
A1: Tantalus Frontier — V162
A2: 15_LotsV159
A3: Prépublication : implémentation et validation du commit restent distinctes.
A5: Lot_ID | B5: Contrat | C5: IDs / périmètre | D5: État technique | E5: État recette | F5: Source / fidélité | G5: Reste ouvert
A6: bishop-annex-circulation | B6: Trajet physique laboratoire / baie synthétique | C6: crew-05-bishop-9 ; science-lab ↔ synthetic-bay ; pont 1 | D6: Implémenté (trajet borné ; réservation physique et marche native pendant le retrait d’alerte) | E6: À exécuter sur le commit publié | F6: Acteur,art, sols 2D et sas apparié natifs ; aucune nouvelle certification 1:1 | G6: Quarantaine, autres annexes, ponts, ascenseurs et corpus artistique complet.

Sheet 16_SourcesV159
A1: Tantalus Frontier — V162
A2: 16_SourcesV159
A3: Prépublication : implémentation et validation du commit restent distinctes.
A5: Source_ID | B5: Titre | C5: Auteur / éditeur | D5: URL consultée | E5: Consulté à (UTC) | F5: SHA256 contenu | G5: Portée | H5: Apport documenté | I5: Limite | J5: Mouvement certifié | K5: Approuvé1:1
A6: V159-REF-001 | B6: Aliens: Fireteam Elite | C6: Cold Iron Studios / official Aliens: Fireteam Elite site | D6: https://www.aliensfireteamelite.com/en/ | E6: 2026-10-18T07:37:40.412148+00:00 | F6: 762d7bd7c455435dab56d7ea4471cd574bc3878feeb7a7eddae3a48c1927ac9f | G6: identity and high-level game design | H6: Official overview of the launch-era game roster, cooperative context and classes. Counts are not a complete current expansion roster. | I6: No per-enemy choreography, frame counts, full DLC archive, or costume-specific film authenticity. | J6: 0 | K6: 0
A7: V159-REF-002 | B7: RELEASE NOTES | Aliens Fireteam Elite | C7: Cold Iron Studios / official release notes | D7: https://www.aliensfireteamelite.com/en/releasenotes/ | E7: 2026-10-18T07:39:51.046186+00:00 | F7: 8f6b7fb64cb00ac2bf718ecf2fcef44b65b38f1ada852607b00791868f6a948a | G7: capability / patch behavior | H7: Official acknowledgement of a grapple mechanic and implementation corrections. Prowler stumble behavior is also present in text. | I7: Does not give a full Prowler animation cycle, victim pin geometry, frame timing or per-species choreography. | J7: 0 | K7: 0
